Workbook

Sheet RawData
A1: Date | B1: Bird | C1: Time | D1: LeftPecks | E1: RightPecks | F1: LeftSeed | G1: RightSeed | H1: IVI (mins) | I1: Northern Cardinal | J1: Tufted Titmouse | K1: Carolina Chickadee | L1: Carolina Wren | M1: Gray Catbird | N1: Red-bellied Woodpecker | O1: Mourning Dove | P1: Common Ground Dove | Q1: Eastern Bluebird | R1: Eastern Phoebe | S1: Pine Warbler
A2: 45935 | B2: Northern Cardinal | C2: 0.65625 | D2: 0 | E2: 5 | F2: Special Finch Food | G2: Golden Safflower
A3: 45935 | B3: Northern Cardinal | C3: 0.65763889 | D3: 1 | E3: 1 | F3: Special Finch Food | G3: Golden Safflower | H3: 2 | I3: 2
A4: 45935 | B4: Northern Cardinal | C4: 0.67569444 | D4: 0 | E4: 3 | F4: Special Finch Food | G4: Golden Safflower | H4: 26 | I4: 26
A5: 45935 | B5: Northern Cardinal | C5: 0.67708333 | D5: 0 | E5: 2 | F5: Special Finch Food | G5: Golden Safflower | H5: 2 | I5: 2
A6: 45935 | B6: Northern Cardinal | C6: 0.67777778 | D6: 0 | E6: 2 | F6: Special Finch Food | G6: Golden Safflower | H6: 0.99999999 | I6: 0.99999999
A7: 45935 | B7: Northern Cardinal | C7: 0.67847222 | D7: 0 | E7: 3 | F7: Special Finch Food | G7: Golden Safflower | H7: 1 | I7: 1
A8: 45935 | B8: Northern Cardinal | C8: 0.67986111 | D8: 0 | E8: 3 | F8: Special Finch Food | G8: Golden Safflower | H8: 2 | I8: 2
A9: 45935 | B9: Tufted Titmouse | C9: 0.68680556 | D9: 0 | E9: 2 | F9: Special Finch Food | G9: Golden Safflower | H9: 10
A10: 45935 | B10: Northern Cardinal | C10: 0.69305556 | D10: 0 | E10: 5 | F10: Special Finch Food | G10: Golden Safflower | H10: 9 | I10: 19
A11: 45935 | B11: Northern Cardinal | C11: 0.69375 | D11: 0 | E11: 5 | F11: Special Finch Food | G11: Golden Safflower | H11: 0.99999999 | I11: 0.99999999
A12: 45935 | B12: Northern Cardinal | C12: 0.69444444 | D12: 0 | E12: 1 | F12: Special Finch Food | G12: Golden Safflower | H12: 1 | I12: 1
A13: 45935 | B13: Northern Cardinal | C13: 0.69791667 | D13: 0 | E13: 5 | F13: Special Finch Food | G13: Golden Safflower | H13: 5 | I13: 5
A14: 45935 | B14: Northern Cardinal | C14: 0.69930556 | D14: 0 | E14: 3 | F14: Special Finch Food | G14: Golden Safflower | H14: 2 | I14: 2
A15: 45935 | B15: Northern Cardinal | C15: 0.7 | D15: 0 | E15: 4 | F15: Special Finch Food | G15: Golden Safflower | H15: 0.99999999 | I15: 0.99999999
A16: 45935 | B16: Northern Cardinal | C16: 0.78680556 | D16: 0 | E16: 3 | F16: Special Finch Food | G16: Golden Safflower | H16: 125 | I16: 125
A17: 45935 | B17: Northern Cardinal | C17: 0.7875 | D17: 0 | E17: 3 | F17: Special Finch Food | G17: Golden Safflower | H17: 0.99999999 | I17: 0.99999999
A18: 45935 | B18: Northern Cardinal | C18: 0.79375 | D18: 0 | E18: 1 | F18: Special Finch Food | G18: Golden Safflower | H18: 9 | I18: 9
A19: 45935 | B19: Northern Cardinal | C19: 0.79444444 | D19: 0 | E19: 2 | F19: Special Finch Food | G19: Golden Safflower | H19: 1 | I19: 1
A20: 45935 | B20: Northern Cardinal | C20: 0.79583333 | D20: 0 | E20: 3 | F20: Special Finch Food | G20: Golden Safflower | H20: 2 | I20: 2
A21: 45936 | B21: Northern Cardinal | C21: 0.30486111 | D21: 0 | E21: 2 | F21: Special Finch Food | G21: Golden Safflower | H21: 733 | I21: 733
... A38: 45936 | B38: Northern Cardinal | C38: 0.42361111 | D38: 0 | E38: 0 | F38: Special Finch Food | G38: Golden Safflower | H38: 0.99999999 | I38: 0.99999999
A39: 45936 | B39: Carolina Chickadee | C39: 0.61875 | D39: 0 | E39: 1 | F39: Special Finch Food | G39: Golden Safflower | H39: 281
A40: 45936 | B40: Northern Cardinal | C40: 0.62013889 | D40: 0 | E40: 1 | F40: Special Finch Food | G40: Golden Safflower | H40: 2 | I40: 283
A41: 45936 | B41: Northern Cardinal | C41: 0.62083333 | D41: 0 | E41: 4 | F41: Special Finch Food | G41: Golden Safflower | H41: 1 | I41: 1
A42: 45936 | B42: Tufted Titmouse | C42: 0.62430556 | D42: 0 | E42: 1 | F42: Special Finch Food | G42: Golden Safflower | H42: 5 | J42: 1350
A43: 45936 | B43: Tufted Titmouse | C43: 0.625 | D43: 0 | E43: 1 | F43: Special Finch Food | G43: Golden Safflower | H43: 1 | J43: 1
A44: 45936 | B44: Tufted Titmouse | C44: 0.62638889 | D44: 0 | E44: 2 | F44: Special Finch Food | G44: Golden Safflower | H44: 2 | J44: 2
A45: 45936 | B45: Tufted Titmouse | C45: 0.62638889 | D45: 0 | E45: 2 | F45: Special Finch Food | G45: Golden Safflower | H45: 0 | J45: 0
A46: 45936 | B46: Carolina Chickadee | C46: 0.62638889 | D46: 0 | E46: 1 | F46: Special Finch Food | G46: Golden Safflower | H46: 0 | K46: 11
A47: 45936 | B47: Northern Cardinal | C47: 0.62638889 | D47: 0 | E47: 1 | F47: Special Finch Food | G47: Golden Safflower | H47: 0 | I47: 8
A48: 45936 | B48: Northern Cardinal | C48: 0.62708333 | D48: 0 | E48: 1 | F48: Special Finch Food | G48: Golden Safflower | H48: 1 | I48: 1
A49: 45936 | B49: Northern Cardinal | C49: 0.62708333 | D49: 0 | E49: 1 | F49: Special Finch Food | G49: Golden Safflower | H49: 0 | I49: 0
A50: 45936 | B50: Northern Cardinal | C50: 0.62777778 | D50: 0 | E50: 6 | F50: Special Finch Food | G50: Golden Safflower | H50: 1 | I50: 1
A51: 45936 | B51: Tufted Titmouse | C51: 0.62986111 | D51: 0 | E51: 1 | F51: Special Finch Food | G51: Golden Safflower | H51: 3 | J51: 5
A52: 45936 | B52: Carolina Chickadee | C52: 0.62986111 | D52: 0 | E52: 1 | F52: Special Finch Food | G52: Golden Safflower | H52: 0 | K52: 5
A53: 45936 | B53: Tufted Titmouse | C53: 0.64375 | D53: 0 | E53: 3 | F53: Special Finch Food | G53: Golden Safflower | H53: 20 | J53: 20
A54: 45936 | B54: Tufted Titmouse | C54: 0.64375 | D54: 0 | E54: 1 | F54: Special Finch Food | G54: Golden Safflower | H54: 0 | J54: 0
A55: 45936 | B55: Tufted Titmouse | C55: 0.64375 | D55: 0 | E55: 1 | F55: Special Finch Food | G55: Golden Safflower | H55: 0 | J55: 0
A56: 45936 | B56: Carolina Chickadee | C56: 0.64513889 | D56: 1 | E56: 0 | F56: Special Finch Food | G56: Golden Safflower | H56: 2 | K56: 22
...

Sheet DailySummaries
A1: Date | B1: Bird | C1: Feeder Visits | D1: Left Pecks | E1: Right Pecks
A2: 45935 | B2: Northern Cardinal | C2: =COUNTIFS(RawData!$B:$B, B$2, RawData!$A:$A, DailySummaries!$A2) -> 18 | D2: =SUMIFS(RawData!$D:$D,RawData!$B:$B,$B2,RawData!$A:$A,DailySummaries!$A2)+1 -> 2 | E2: =SUMIFS(RawData!$E:$E,RawData!$B:$B,$B2,RawData!$A:$A,DailySummaries!$A2)+1 -> 55
A3: 45935 | B3: Tufted Titmouse | C3: =COUNTIFS(RawData!$B:$B, $B3, RawData!$A:$A, DailySummaries!$A3) -> 1 | D3: =SUMIFS(RawData!$D:$D,RawData!$B:$B,$B3,RawData!$A:$A,DailySummaries!$A3)+1 -> 1 | E3: =SUMIFS(RawData!$E:$E,RawData!$B:$B,$B3,RawData!$A:$A,DailySummaries!$A3)+1 -> 3
A4: 45936 | B4: Northern Cardinal | C4: =COUNTIFS(RawData!$B:$B, $B4, RawData!$A:$A, DailySummaries!$A4) -> 51 | D4: =SUMIFS(RawData!$D:$D,RawData!$B:$B,$B4,RawData!$A:$A,DailySummaries!$A4)+1 -> 3 | E4: =SUMIFS(RawData!$E:$E,RawData!$B:$B,$B4,RawData!$A:$A,DailySummaries!$A4)+1 -> 124
A5: 45936 | B5: Tufted Titmouse | C5: =COUNTIFS(RawData!$B:$B, $B5, RawData!$A:$A, DailySummaries!$A5) -> 8 | D5: =SUMIFS(RawData!$D:$D,RawData!$B:$B,$B5,RawData!$A:$A,DailySummaries!$A5)+1 -> 1 | E5: =SUMIFS(RawData!$E:$E,RawData!$B:$B,$B5,RawData!$A:$A,DailySummaries!$A5)+1 -> 13
A6: 45936 | B6: Gray Catbird | C6: =COUNTIFS(RawData!$B:$B, $B6, RawData!$A:$A, DailySummaries!$A6) -> 1 | D6: =SUMIFS(RawData!$D:$D,RawData!$B:$B,$B6,RawData!$A:$A,DailySummaries!$A6)+1 -> 1 | E6: =SUMIFS(RawData!$E:$E,RawData!$B:$B,$B6,RawData!$A:$A,DailySummaries!$A6)+1 -> 2
A7: 45936 | B7: Carolina Chickadee | C7: =COUNTIFS(RawData!$B:$B, $B7, RawData!$A:$A, DailySummaries!$A7) -> 5 | D7: =SUMIFS(RawData!$D:$D,RawData!$B:$B,$B7,RawData!$A:$A,DailySummaries!$A7)+1 -> 2 | E7: =SUMIFS(RawData!$E:$E,RawData!$B:$B,$B7,RawData!$A:$A,DailySummaries!$A7)+1 -> 5
A8: 45937 | B8: Northern Cardinal | C8: =COUNTIFS(RawData!$B:$B, $B8, RawData!$A:$A, DailySummaries!$A8) -> 39 | D8: =SUMIFS(RawData!$D:$D,RawData!$B:$B,$B8,RawData!$A:$A,DailySummaries!$A8)+1 -> 2 | E8: =SUMIFS(RawData!$E:$E,RawData!$B:$B,$B8,RawData!$A:$A,DailySummaries!$A8)+1 -> 94
A9: 45937 | B9: Tufted Titmouse | C9: =COUNTIFS(RawData!$B:$B, $B9, RawData!$A:$A, DailySummaries!$A9) -> 22 | D9: =SUMIFS(RawData!$D:$D,RawData!$B:$B,$B9,RawData!$A:$A,DailySummaries!$A9)+1 -> 1 | E9: =SUMIFS(RawData!$E:$E,RawData!$B:$B,$B9,RawData!$A:$A,DailySummaries!$A9)+1 -> 56
A10: 45937 | B10: Carolina Chickadee | C10: =COUNTIFS(RawData!$B:$B, $B10, RawData!$A:$A, DailySummaries!$A10) -> 28 | D10: =SUMIFS(RawData!$D:$D,RawData!$B:$B,$B10,RawData!$A:$A,DailySummaries!$A10)+1 -> 2 | E10: =SUMIFS(RawData!$E:$E,RawData!$B:$B,$B10,RawData!$A:$A,DailySummaries!$A10)+1 -> 33
A11: 45937 | B11: Carolina Wren | C11: =COUNTIFS(RawData!$B:$B, $B11, RawData!$A:$A, DailySummaries!$A11) -> 2 | D11: =SUMIFS(RawData!$D:$D,RawData!$B:$B,$B11,RawData!$A:$A,DailySummaries!$A11)+1 -> 18 | E11: =SUMIFS(RawData!$E:$E,RawData!$B:$B,$B11,RawData!$A:$A,DailySummaries!$A11)+1 -> 3
A12: 45938 | B12: Northern Cardinal | C12: =COUNTIFS(RawData!$B:$B, $B12, RawData!$A:$A, DailySummaries!$A12) -> 49 | D12: =SUMIFS(RawData!$D:$D,RawData!$B:$B,$B12,RawData!$A:$A,DailySummaries!$A12)+1 -> 22 | E12: =SUMIFS(RawData!$E:$E,RawData!$B:$B,$B12,RawData!$A:$A,DailySummaries!$A12)+1 -> 139
A13: 45938 | B13: Carolina Chickadee | C13: =COUNTIFS(RawData!$B:$B, $B13, RawData!$A:$A, DailySummaries!$A13) -> 61 | D13: =SUMIFS(RawData!$D:$D,RawData!$B:$B,$B13,RawData!$A:$A,DailySummaries!$A13)+1 -> 2 | E13: =SUMIFS(RawData!$E:$E,RawData!$B:$B,$B13,RawData!$A:$A,DailySummaries!$A13)+1 -> 82
A14: 45938 | B14: Tufted Titmouse | C14: =COUNTIFS(RawData!$B:$B, $B14, RawData!$A:$A, DailySummaries!$A14) -> 28 | D14: =SUMIFS(RawData!$D:$D,RawData!$B:$B,$B14,RawData!$A:$A,DailySummaries!$A14)+1 -> 2 | E14: =SUMIFS(RawData!$E:$E,RawData!$B:$B,$B14,RawData!$A:$A,DailySummaries!$A14)+1 -> 65
... A48: 45947 | B48: Northern Cardinal | C48: =COUNTIFS(RawData!$B:$B, $B48, RawData!$A:$A, DailySummaries!$A48) -> 56 | D48: =SUMIFS(RawData!$D:$D,RawData!$B:$B,$B48,RawData!$A:$A,DailySummaries!$A48)+1 -> 7 | E48: =SUMIFS(RawData!$E:$E,RawData!$B:$B,$B48,RawData!$A:$A,DailySummaries!$A48)+1 -> 171
A49: =A48 -> 45947 | B49: Carolina Chickadee | C49: =COUNTIFS(RawData!$B:$B, $B49, RawData!$A:$A, DailySummaries!$A49) -> 26 | D49: =SUMIFS(RawData!$D:$D,RawData!$B:$B,$B49,RawData!$A:$A,DailySummaries!$A49)+1 -> 48 | E49: =SUMIFS(RawData!$E:$E,RawData!$B:$B,$B49,RawData!$A:$A,DailySummaries!$A49)+1 -> 26
A50: =A49 -> 45947 | B50: Carolina Wren | C50: =COUNTIFS(RawData!$B:$B, $B50, RawData!$A:$A, DailySummaries!$A50) -> 12 | D50: =SUMIFS(RawData!$D:$D,RawData!$B:$B,$B50,RawData!$A:$A,DailySummaries!$A50)+1 -> 76 | E50: =SUMIFS(RawData!$E:$E,RawData!$B:$B,$B50,RawData!$A:$A,DailySummaries!$A50)+1 -> 41
A51: =A50 -> 45947 | B51: Common Ground Dove | C51: =COUNTIFS(RawData!$B:$B, $B51, RawData!$A:$A, DailySummaries!$A51) -> 0 | D51: =SUMIFS(RawData!$D:$D,RawData!$B:$B,$B51,RawData!$A:$A,DailySummaries!$A51)+1 -> 1 | E51: =SUMIFS(RawData!$E:$E,RawData!$B:$B,$B51,RawData!$A:$A,DailySummaries!$A51)+1 -> 1
A52: =A51 -> 45947 | B52: Mourning Dove | C52: =COUNTIFS(RawData!$B:$B, $B52, RawData!$A:$A, DailySummaries!$A52) -> 32 | D52: =SUMIFS(RawData!$D:$D,RawData!$B:$B,$B52,RawData!$A:$A,DailySummaries!$A52)+1 -> 446 | E52: =SUMIFS(RawData!$E:$E,RawData!$B:$B,$B52,RawData!$A:$A,DailySummaries!$A52)+1 -> 57
A53: =A52 -> 45947 | B53: Tufted Titmouse | C53: =COUNTIFS(RawData!$B:$B, $B53, RawData!$A:$A, DailySummaries!$A53) -> 10 | D53: =SUMIFS(RawData!$D:$D,RawData!$B:$B,$B53,RawData!$A:$A,DailySummaries!$A53)+1 -> 1 | E53: =SUMIFS(RawData!$E:$E,RawData!$B:$B,$B53,RawData!$A:$A,DailySummaries!$A53)+1 -> 22
A54: 45948 | B54: Northern Cardinal | C54: =COUNTIFS(RawData!$B:$B, $B54, RawData!$A:$A, DailySummaries!$A54) -> 25 | D54: =SUMIFS(RawData!$D:$D,RawData!$B:$B,$B54,RawData!$A:$A,DailySummaries!$A54)+1 -> 2 | E54: =SUMIFS(RawData!$E:$E,RawData!$B:$B,$B54,RawData!$A:$A,DailySummaries!$A54)+1 -> 73
A55: 45948 | B55: Carolina Chickadee | C55: =COUNTIFS(RawData!$B:$B, $B55, RawData!$A:$A, DailySummaries!$A55) -> 6 | D55: =SUMIFS(RawData!$D:$D,RawData!$B:$B,$B55,RawData!$A:$A,DailySummaries!$A55)+1 -> 5 | E55: =SUMIFS(RawData!$E:$E,RawData!$B:$B,$B55,RawData!$A:$A,DailySummaries!$A55)+1 -> 6
A56: 45948 | B56: Carolina Wren | C56: =COUNTIFS(RawData!$B:$B, $B56, RawData!$A:$A, DailySummaries!$A56) -> 11 | D56: =SUMIFS(RawData!$D:$D,RawData!$B:$B,$B56,RawData!$A:$A,DailySummaries!$A56)+1 -> 83 | E56: =SUMIFS(RawData!$E:$E,RawData!$B:$B,$B56,RawData!$A:$A,DailySummaries!$A56)+1 -> 19
A57: 45948 | B57: Tufted Titmouse | C57: =COUNTIFS(RawData!$B:$B, $B57, RawData!$A:$A, DailySummaries!$A57) -> 18 | D57: =SUMIFS(RawData!$D:$D,RawData!$B:$B,$B57,RawData!$A:$A,DailySummaries!$A57)+1 -> 2 | E57: =SUMIFS(RawData!$E:$E,RawData!$B:$B,$B57,RawData!$A:$A,DailySummaries!$A57)+1 -> 26
A58: 45948 | B58: Mourning Dove | C58: =COUNTIFS(RawData!$B:$B, $B58, RawData!$A:$A, DailySummaries!$A58) -> 4 | D58: =SUMIFS(RawData!$D:$D,RawData!$B:$B,$B58,RawData!$A:$A,DailySummaries!$A58)+1 -> 1 | E58: =SUMIFS(RawData!$E:$E,RawData!$B:$B,$B58,RawData!$A:$A,DailySummaries!$A58)+1 -> 19
A59: 45949 | B59: Northern Cardinal | C59: =COUNTIFS(RawData!$B:$B, $B59, RawData!$A:$A, DailySummaries!$A59) -> 56 | D59: =SUMIFS(RawData!$D:$D,RawData!$B:$B,$B59,RawData!$A:$A,DailySummaries!$A59)+1 -> 5 | E59: =SUMIFS(RawData!$E:$E,RawData!$B:$B,$B59,RawData!$A:$A,DailySummaries!$A59)+1 -> 129
A60: 45949 | B60: Carolina Wren | C60: =COUNTIFS(RawData!$B:$B, $B60, RawData!$A:$A, DailySummaries!$A60) -> 17 | D60: =SUMIFS(RawData!$D:$D,RawData!$B:$B,$B60,RawData!$A:$A,DailySummaries!$A60)+1 -> 113 | E60: =SUMIFS(RawData!$E:$E,RawData!$B:$B,$B60,RawData!$A:$A,DailySummaries!$A60)+1 -> 9
A61: 45949 | B61: Mourning Dove | C61: =COUNTIFS(RawData!$B:$B, $B61, RawData!$A:$A, DailySummaries!$A61) -> 23 | D61: =SUMIFS(RawData!$D:$D,RawData!$B:$B,$B61,RawData!$A:$A,DailySummaries!$A61)+1 -> 242 | E61: =SUMIFS(RawData!$E:$E,RawData!$B:$B,$B61,RawData!$A:$A,DailySummaries!$A61)+1 -> 54
A62: 45949 | B62: Common Ground Dove | C62: =COUNTIFS(RawData!$B:$B, $B62, RawData!$A:$A, DailySummaries!$A62) -> 0 | D62: =SUMIFS(RawData!$D:$D,RawData!$B:$B,$B62,RawData!$A:$A,DailySummaries!$A62)+1 -> 1 | E62: =SUMIFS(RawData!$E:$E,RawData!$B:$B,$B62,RawData!$A:$A,DailySummaries!$A62)+1 -> 1
A63: 45950 | B63: Northern Cardinal | C63: =COUNTIFS(RawData!$B:$B, $B63, RawData!$A:$A, DailySummaries!$A63) -> 38 | D63: =SUMIFS(RawData!$D:$D,RawData!$B:$B,$B63,RawData!$A:$A,DailySummaries!$A63)+1 -> 4 | E63: =SUMIFS(RawData!$E:$E,RawData!$B:$B,$B63,RawData!$A:$A,DailySummaries!$A63)+1 -> 108
A64: 45950 | B64: Carolina Chickadee | C64: =COUNTIFS(RawData!$B:$B, $B64, RawData!$A:$A, DailySummaries!$A64) -> 11 | D64: =SUMIFS(RawData!$D:$D,RawData!$B:$B,$B64,RawData!$A:$A,DailySummaries!$A64)+1 -> 2 | E64: =SUMIFS(RawData!$E:$E,RawData!$B:$B,$B64,RawData!$A:$A,DailySummaries!$A64)+1 -> 8
A65: 45950 | B65: Carolina Wren | C65: =COUNTIFS(RawData!$B:$B, $B65, RawData!$A:$A, DailySummaries!$A65) -> 15 | D65: =SUMIFS(RawData!$D:$D,RawData!$B:$B,$B65,RawData!$A:$A,DailySummaries!$A65)+1 -> 84 | E65: =SUMIFS(RawData!$E:$E,RawData!$B:$B,$B65,RawData!$A:$A,DailySummaries!$A65)+1 -> 32
... A112: 45960 | B112: Northern Cardinal | C112: =COUNTIFS(RawData!$B:$B, $B112, RawData!$A:$A, DailySummaries!$A112) -> 24 | D112: =SUMIFS(RawData!$D:$D,RawData!$B:$B,$B112,RawData!$A:$A,DailySummaries!$A112)+1 -> 1 | E112: =SUMIFS(RawData!$E:$E,RawData!$B:$B,$B112,RawData!$A:$A,DailySummaries!$A112)+1 -> 66
A113: =A112 -> 45960 | B113: Mourning Dove | C113: =COUNTIFS(RawData!$B:$B, $B113, RawData!$A:$A, DailySummaries!$A113) -> 147 | D113: =SUMIFS(RawData!$D:$D,RawData!$B:$B,$B113,RawData!$A:$A,DailySummaries!$A113)+1 -> 967 | E113: =SUMIFS(RawData!$E:$E,RawData!$B:$B,$B113,RawData!$A:$A,DailySummaries!$A113)+1 -> 419
A114: =A113 -> 45960 | B114: Carolina Chickadee | C114: =COUNTIFS(RawData!$B:$B, $B114, RawData!$A:$A, DailySummaries!$A114) -> 7 | D114: =SUMIFS(RawData!$D:$D,RawData!$B:$B,$B114,RawData!$A:$A,DailySummaries!$A114)+1 -> 1 | E114: =SUMIFS(RawData!$E:$E,RawData!$B:$B,$B114,RawData!$A:$A,DailySummaries!$A114)+1 -> 8
A115: =A114 -> 45960 | B115: Carolina Wren | C115: =COUNTIFS(RawData!$B:$B, $B115, RawData!$A:$A, DailySummaries!$A115) -> 4 | D115: =SUMIFS(RawData!$D:$D,RawData!$B:$B,$B115,RawData!$A:$A,DailySummaries!$A115)+1 -> 32 | E115: =SUMIFS(RawData!$E:$E,RawData!$B:$B,$B115,RawData!$A:$A,DailySummaries!$A115)+1 -> 9
A116: 45961 | B116: Northern Cardinal | C116: =COUNTIFS(RawData!$B:$B, $B116, RawData!$A:$A, DailySummaries!$A116) -> 43 | D116: =SUMIFS(RawData!$D:$D,RawData!$B:$B,$B116,RawData!$A:$A,DailySummaries!$A116)+1 -> 3 | E116: =SUMIFS(RawData!$E:$E,RawData!$B:$B,$B116,RawData!$A:$A,DailySummaries!$A116)+1 -> 136
A117: =A116 -> 45961 | B117: Mourning Dove | C117: =COUNTIFS(RawData!$B:$B, $B117, RawData!$A:$A, DailySummaries!$A117) -> 189 | D117: =SUMIFS(RawData!$D:$D,RawData!$B:$B,$B117,RawData!$A:$A,DailySummaries!$A117)+1 -> 932 | E117: =SUMIFS(RawData!$E:$E,RawData!$B:$B,$B117,RawData!$A:$A,DailySummaries!$A117)+1 -> 483
A118: =A117 -> 45961 | B118: Carolina Chickadee | C118: =COUNTIFS(RawData!$B:$B, $B118, RawData!$A:$A, DailySummaries!$A118) -> 18 | D118: =SUMIFS(RawData!$D:$D,RawData!$B:$B,$B118,RawData!$A:$A,DailySummaries!$A118)+1 -> 3 | E118: =SUMIFS(RawData!$E:$E,RawData!$B:$B,$B118,RawData!$A:$A,DailySummaries!$A118)+1 -> 18
A119: =A118 -> 45961 | B119: Carolina Wren | C119: =COUNTIFS(RawData!$B:$B, $B119, RawData!$A:$A, DailySummaries!$A119) -> 3 | D119: =SUMIFS(RawData!$D:$D,RawData!$B:$B,$B119,RawData!$A:$A,DailySummaries!$A119)+1 -> 35 | E119: =SUMIFS(RawData!$E:$E,RawData!$B:$B,$B119,RawData!$A:$A,DailySummaries!$A119)+1 -> 1
...
